Workbook
Name Slicer_Financial_Year: #N/A
Name Slicer_Financial_Year1: #N/A
Name Slicer_Financial_Year2: #N/A
Name Slicer_Hospital: #N/A
Name Slicer_Hospital1: #N/A
Name Slicer_Hospital2: #N/A
Name Slicer_Hospital3: #N/A
Name Slicer_Operating_Theatre: #N/A
Name Slicer_Responsible_Consultant: #N/A
Name Slicer_ReviewConFinancialYear: #N/A
Name Slicer_ReviewConHospital: #N/A
Name Slicer_ReviewConMonth: #N/A
Name Slicer_ReviewConOperatingTheatre: #N/A
Name Slicer_ReviewConResponsibleConsultant: #N/A
Name Slicer_ReviewConServiceArea: #N/A
Name Slicer_ReviewConSessionSpecialty: #N/A
Name Slicer_ReviewConTheatreType: #N/A
Name Slicer_ReviewLoadFinancialYear: #N/A
Name Slicer_ReviewLoadHospital: #N/A
Name Slicer_ReviewLoadMonth: #N/A
Name Slicer_ReviewLoadOperatingTheatre: #N/A
Name Slicer_ReviewLoadResponsibleConsultant: #N/A
Name Slicer_ReviewLoadServiceArea: #N/A
Name Slicer_ReviewLoadSessionSpecialty: #N/A
Name Slicer_ReviewLoadTheatreType: #N/A
Name Slicer_ReviewSpecFinancialYear: #N/A
Name Slicer_ReviewSpecHospital: #N/A
Name Slicer_ReviewSpecMonth: #N/A
Name Slicer_ReviewSpecOperatingTheatre: #N/A
Name Slicer_ReviewSpecResponsibleConsultant: #N/A
Name Slicer_ReviewSpecServiceArea: #N/A
Name Slicer_ReviewSpecSessionSpecialty: #N/A
Name Slicer_ReviewSpecTheatreType: #N/A
Name Slicer_Service_Area: #N/A
Name Slicer_Service_Area1: #N/A
Name Slicer_Service_Area2: #N/A
Name Slicer_Session_Specialty: #N/A
Name Slicer_Session_Specialty1: #N/A
Name Slicer_Session_Specialty2: #N/A
Name Slicer_Session_Specialty3: #N/A
Name Slicer_Theatre_Type: #N/A
Name Slicer_Theatre_Type1: #N/A
Name Slicer_Theatre_Type2: #N/A
Name Slicer_Theatre_Type3: #N/A
Name WeeklyEnd: IF('Weekly Review'!$E$19="",TODAY()-1,INT('Weekly Review'!$E$19))
Name WeeklyPageCount: Setup!$V$28
Name WeeklyStart: WeeklyEnd-6

Sheet Utilisation - Detail by Theatre
B2: THEATRE UTILISATION — DETAIL BY THEATRE
B3: ="Sessions: "&TEXT(IFERROR(GETPIVOTDATA("Number",Setup!E12,"Record Type","No. of sessions"),0),"#,##0")&" Patient encounters: "&TEXT(IFERROR(GETPIVOTDATA("Number",Setup!E12,"Record Type","No. of patients"),0),"#,##0") -> Sessions: 1,014 Patient encounters: 4,050
B4: After Refresh All finishes, refresh this pivot. Patient counts require both first start and last end. Double-click counts for session or patient detail.
B17: Counts by theatre, slot duration (minutes), and month
B18: Number | F18: Month
B19: Theatre Type | C19: Operating Theatre | D19: Session Duration | E19: Record Type | F19: 46174 | G19: 46204 | H19: 46235 | I19: Grand Total
B20: DPU | C20: CAH DPU 1 | D20: 180 | E20: No. of sessions | F20: 1 | G20: 1 | H20: 0 | I20: 2
E21: No. of patients | F21: 4 | G21: 4 | H21: 0 | I21: 8
D22: 210 | E22: No. of sessions | F22: 0 | G22: 2 | H22: 1 | I22: 3
E23: No. of patients | F23: 0 | G23: 8 | H23: 4 | I23: 12
D24: 240 | E24: No. of sessions | F24: 2 | G24: 2 | H24: 3 | I24: 7
E25: No. of patients | F25: 8 | G25: 8 | H25: 12 | I25: 28
D26: 270 | E26: No. of sessions | F26: 1 | G26: 3 | H26: 4 | I26: 8
E27: No. of patients | F27: 4 | G27: 12 | H27: 16 | I27: 32
D28: 300 | E28: No. of sessions | F28: 0 | G28: 1 | H28: 2 | I28: 3
E29: No. of patients | F29: 0 | G29: 2 | H29: 8 | I29: 10
D30: 360 | E30: No. of sessions | F30: 0 | G30: 0 | H30: 2 | I30: 2
E31: No. of patients | F31: 0 | G31: 0 | H31: 8 | I31: 8
D32: 420 | E32: No. of sessions | F32: 1 | G32: 0 | H32: 0 | I32: 1
E33: No. of patients | F33: 4 | G33: 0 | H33: 0 | I33: 4
D34: 480 | E34: No. of sessions | F34: 1 | G34: 5 | H34: 3 | I34: 9
E35: No. of patients | F35: 4 | G35: 20 | H35: 12 | I35: 36
D36: 540 | E36: No. of sessions | F36: 2 | G36: 1 | H36: 3 | I36: 6
E37: No. of patients | F37: 8 | G37: 4 | H37: 12 | I37: 24
C38: ST STY THEATRE 1 | D38: 180 | E38: No. of sessions | F38: 0 | G38: 1 | H38: 1 | I38: 2
E39: No. of patients | F39: 0 | G39: 4 | H39: 4 | I39: 8
D40: 210 | E40: No. of sessions | F40: 1 | G40: 0 | H40: 2 | I40: 3
E41: No. of patients | F41: 4 | G41: 0 | H41: 8 | I41: 12
D42: 240 | E42: No. of sessions | F42: 2 | G42: 5 | H42: 0 | I42: 7
E43: No. of patients | F43: 8 | G43: 20 | H43: 0 | I43: 28
D44: 270 | E44: No. of sessions | F44: 3 | G44: 2 | H44: 1 | I44: 6
E45: No. of patients | F45: 12 | G45: 8 | H45: 4 | I45: 24
D46: 300 | E46: No. of sessions | F46: 0 | G46: 1 | H46: 0 | I46: 1
E47: No. of patients | F47: 0 | G47: 4 | H47: 0 | I47: 4
D48: 360 | E48: No. of sessions | F48: 3 | G48: 0 | H48: 3 | I48: 6
E49: No. of patients | F49: 12 | G49: 0 | H49: 12 | I49: 24
D50: 420 | E50: No. of sessions | F50: 0 | G50: 1 | H50: 0 | I50: 1
E51: No. of patients | F51: 0 | G51: 4 | H51: 0 | I51: 4
D52: 480 | E52: No. of sessions | F52: 6 | G52: 6 | H52: 2 | I52: 14
E53: No. of patients | F53: 24 | G53: 24 | H53: 8 | I53: 56
...

Sheet Utilisation - Detail
B2: THEATRE UTILISATION — DETAIL
B3: Session Duration includes all recorded sessions with valid planned slots. Run/op percentages use complete-timing planned minutes; see coverage below. Refresh this pivot after Refresh All.
B4: ="Timing coverage (slicers): "&TEXT(GETPIVOTDATA("Timing sessions",Setup!$E$2),"#,##0")&" / "&TEXT(GETPIVOTDATA("All sessions",Setup!$E$2),"#,##0")&" sessions ("&IF(GETPIVOTDATA("All sessions",Setup!$E$2)=0,"no sessions",TEXT(GETPIVOTDATA("Timing sessions",Setup!$E$2)/GETPIVOTDATA("All sessions",Setup!$E$2),"0.0%"))&"). Excluded: "&TEXT(GETPIVOTDATA("Excluded sessions",Setup!$E$2),"#,##0")&". Planned minutes covered: "&IF(GETPIVOTDATA("All planned minutes",Setup!$E$2)=0,"no planned minutes",TEXT(GETPIVOTDATA("Timing planned minutes",Setup!$E$2)/GETPIVOTDATA("All planned minutes",Setup!$E$2),"0.0%")) -> Timing coverage (slicers): 1,014 / 1,014 sessions (100.0%). Excluded: 0. Planned minutes covered: 100.0%
E18: Financial Year | F18: Month
E19: 26/27 | H19: Total
B20: Trust | C20: Hospital | D20: Values | E20: 46174 | F20: 46204 | G20: 46235
B21: Southern | C21: Craigavon | D21: No. of Sessions | E21: 160 | F21: 167 | G21: 179 | H21: 506
D22: No. of Patients | E22: 640 | F22: 666 | G22: 714 | H22: 2020
D23: Session Duration (Mins) | E23: 53130 | F23: 56910 | G23: 64020 | H23: 174060
D24: Run Time (Mins) | E24: 48071 | F24: 51498 | G24: 57188 | H24: 156757
D25: Op Time (Mins) | E25: 33282 | F25: 35904 | G25: 40007 | H25: 109193
D26: % Run Time | E26: 0.90478073 | F26: 0.90490248 | G26: 0.89328335 | H26: 0.90059175
D27: % Op Time | E27: 0.62642575 | F27: 0.63089088 | G27: 0.62491409 | H27: 0.62732966
C28: Daisy Hill | D28: No. of Sessions | E28: 129 | F28: 123 | G28: 118 | H28: 370
D29: No. of Patients | E29: 516 | F29: 492 | G29: 472 | H29: 1480
D30: Session Duration (Mins) | E30: 46020 | F30: 43200 | G30: 38970 | H30: 128190
D31: Run Time (Mins) | E31: 41782 | F31: 39226 | G31: 35278 | H31: 116286
D32: Op Time (Mins) | E32: 29579 | F32: 27224 | G32: 24408 | H32: 81211
D33: % Run Time | E33: 0.9079096 | F33: 0.90800926 | G33: 0.90526046 | H33: 0.90713784
D34: % Op Time | E34: 0.64274229 | F34: 0.63018519 | G34: 0.62632794 | H34: 0.63352056
C35: South Tyrone | D35: No. of Sessions | E35: 49 | F35: 48 | G35: 41 | H35: 138
D36: No. of Patients | E36: 194 | F36: 192 | G36: 164 | H36: 550
D37: Session Duration (Mins) | E37: 18390 | F37: 17430 | G37: 15690 | H37: 51510
D38: Run Time (Mins) | E38: 16503 | F38: 15871 | G38: 14353 | H38: 46727
D39: Op Time (Mins) | E39: 11752 | F39: 11187 | G39: 10055 | H39: 32994
D40: % Run Time | E40: 0.89738989 | F40: 0.91055651 | G40: 0.91478649 | H40: 0.90714424
D41: % Op Time | E41: 0.63904296 | F41: 0.64182444 | G41: 0.64085405 | H41: 0.64053582
B42: Total No. of Sessions | E42: 338 | F42: 338 | G42: 338 | H42: 1014
B43: Total No. of Patients | E43: 1350 | F43: 1350 | G43: 1350 | H43: 4050
B44: Total Session Duration (Mins) | E44: 117540 | F44: 117540 | G44: 118680 | H44: 353760
B45: Total Run Time (Mins) | E45: 106356 | F45: 106595 | G45: 106819 | H45: 319770
B46: Total Op Time (Mins) | E46: 74613 | F46: 74315 | G46: 74470 | H46: 223398
B47: Total % Run Time | E47: 0.90484941 | F47: 0.90688276 | G47: 0.90005898 | H47: 0.90391791
B48: Total % Op Time | E48: 0.63478816 | F48: 0.63225285 | G48: 0.62748568 | H48: 0.63149593

Sheet Utilisation - Start Finish Time
B2: THEATRE UTILISATION — START AND FINISH TIMES
B3: HSCB allowance: On Time includes 10 minutes either side; Early/Late are outside. After Refresh All finishes, refresh this PivotTable.
B4: ="Classified sessions (slicers): "&TEXT(GETPIVOTDATA("Sessions",Setup!$E$18,"Classification Status","Classified"),"#,##0")&" / "&TEXT(GETPIVOTDATA("Sessions",Setup!$E$18),"#,##0")&". Excluded: "&TEXT(GETPIVOTDATA("Sessions",Setup!$E$18,"Classification Status","Unclassified"),"#,##0")&". Chart heights show proportions; labels show counts." -> Classified sessions (slicers): 1,014 / 1,014. Excluded: 0. Chart heights show proportions; labels show counts.
B30: Session counts by start and finish type
B31: Sessions | E31: Financial Year | F31: Month
E32: 26/27 | H32: Total
B33: Trust | C33: Start Type | D33: Finish Type | E33: 46174 | F33: 46204 | G33: 46235
B34: Southern | C34: Early Start | D34: Early Finish | E34: 0 | F34: 0 | G34: 0 | H34: 0
D35: On Time | E35: 0 | F35: 0 | G35: 0 | H35: 0
D36: Late Finish | E36: 0 | F36: 0 | G36: 0 | H36: 0
C37: On Time | D37: Early Finish | E37: 272 | F37: 270 | G37: 267 | H37: 809
D38: On Time | E38: 10 | F38: 6 | G38: 10 | H38: 26
D39: Late Finish | E39: 0 | F39: 0 | G39: 0 | H39: 0
C40: Late Start | D40: Early Finish | E40: 53 | F40: 59 | G40: 57 | H40: 169
D41: On Time | E41: 3 | F41: 3 | G41: 4 | H41: 10
D42: Late Finish | E42: 0 | F42: 0 | G42: 0 | H42: 0
B43: Total | E43: 338 | F43: 338 | G43: 338 | H43: 1014

Sheet Specialty Utilisation
B2: THEATRE UTILISATION — SPECIALTY
B3: Monthly use by specialty, hospital and theatre. Timing measures use complete sessions.
B4: ="Timed sessions: "&TEXT(GETPIVOTDATA("Timed Sessions",$B$18),"#,##0")&" / "&TEXT(GETPIVOTDATA("No. of Sessions",$B$18),"#,##0")&". Timing percentages use matched complete sessions. On Time includes exactly 10 minutes early or late." -> Timed sessions: 1,014 / 1,014. Timing percentages use matched complete sessions. On Time includes exactly 10 minutes early or late.
B5: Double-click a value for the contributing sessions. Patient-level drilldown remains on Utilisation - Detail by Theatre. Refresh this pivot after Refresh All finishes.
F18: Financial Year | G18: Month
F19: 26/27 | I19: Total
B20: Session Specialty | C20: Hospital | D20: Operating Theatre | E20: Values | F20: 46174 | G20: 46204 | H20: 46235
B21: Emergency Surgery | C21: Craigavon | D21: ST CAH MAIN THEATRE 1 | E21: No. of Sessions | H21: 1 | I21: 1
E22: No. of Patients | H22: 2 | I22: 2
E23: Planned Time (Mins) | H23: 1440 | I23: 1440
E24: Planned Time - Timed (Mins) | H24: 1440 | I24: 1440
E25: Run Time (Mins) | F25: — | G25: — | H25: 358 | I25: 358
E26: Op Time (Mins) | F26: — | G26: — | H26: 95 | I26: 95
E27: % Run Time | F27: — | G27: — | H27: 0.24861111 | I27: 0.24861111
E28: % Op Time | F28: — | G28: — | H28: 0.065972222 | I28: 0.065972222
E29: Timed Sessions | H29: 1 | I29: 1
E30: % Timing Coverage | F30: — | G30: — | H30: 1 | I30: 1
E31: Early Start Sessions | H31: 0 | I31: 0
E32: On-Time Start Sessions | H32: 0 | I32: 0
E33: Late Start Sessions | H33: 1 | I33: 1
E34: Early Finish Sessions | H34: 1 | I34: 1
E35: On-Time Finish Sessions | H35: 0 | I35: 0
E36: Late Finish Sessions | H36: 0 | I36: 0
E37: % On-Time Starts | F37: — | G37: — | H37: 0 | I37: 0
E38: % On-Time Finishes | F38: — | G38: — | H38: 0 | I38: 0
B39: ENT | C39: Craigavon | D39: CAH DPU 1 | E39: No. of Sessions | F39: 2 | G39: 2 | H39: 3 | I39: 7
E40: No. of Patients | F40: 8 | G40: 8 | H40: 12 | I40: 28
E41: Planned Time (Mins) | F41: 780 | G41: 480 | H41: 1320 | I41: 2580
E42: Planned Time - Timed (Mins) | F42: 780 | G42: 480 | H42: 1320 | I42: 2580
E43: Run Time (Mins) | F43: 714 | G43: 435 | H43: 1180 | I43: 2329
E44: Op Time (Mins) | F44: 535 | G44: 274 | H44: 876 | I44: 1685
E45: % Run Time | F45: 0.91538462 | G45: 0.90625 | H45: 0.89393939 | I45: 0.90271318
E46: % Op Time | F46: 0.68589744 | G46: 0.57083333 | H46: 0.66363636 | I46: 0.65310078
E47: Timed Sessions | F47: 2 | G47: 2 | H47: 3 | I47: 7
E48: % Timing Coverage | F48: 1 | G48: 1 | H48: 1 | I48: 1
E49: Early Start Sessions | F49: 0 | G49: 0 | H49: 0 | I49: 0
E50: On-Time Start Sessions | F50: 1 | G50: 1 | H50: 1 | I50: 3
E51: Late Start Sessions | F51: 1 | G51: 1 | H51: 2 | I51: 4
... E56: % On-Time Finishes | F56: 0 | G56: 0.5 | H56: 0 | I56: 0.14285714
D57: ST CAH MAIN THEATRE 1 | E57: No. of Sessions | F57: 1 | H57: 6 | I57: 7
...

Sheet Consultant Utilisation
B2: THEATRE UTILISATION — RESPONSIBLE CONSULTANT
B3: Sessions are attributed to the recorded responsible consultant. Shared or incomplete attribution is shown separately.
B4: ="Timed sessions: "&TEXT(GETPIVOTDATA("Timed Sessions",$B$18),"#,##0")&" / "&TEXT(GETPIVOTDATA("No. of Sessions",$B$18),"#,##0")&". Timing percentages use matched complete sessions. On Time includes exactly 10 minutes early or late." -> Timed sessions: 1,014 / 1,014. Timing percentages use matched complete sessions. On Time includes exactly 10 minutes early or late.
B5: Double-click a value for the contributing sessions. Patient-level drilldown remains on Utilisation - Detail by Theatre. Refresh this pivot after Refresh All finishes.
D18: Financial Year | E18: Month
D19: 26/27 | G19: Total
B20: Responsible Consultant | C20: Values | D20: 46174 | E20: 46204 | F20: 46235
B21: Dr David Strong | C21: No. of Sessions | F21: 1 | G21: 1
C22: No. of Patients | F22: 2 | G22: 2
C23: Planned Time (Mins) | F23: 1440 | G23: 1440
C24: Planned Time - Timed (Mins) | F24: 1440 | G24: 1440
C25: Run Time (Mins) | D25: — | E25: — | F25: 358 | G25: 358
C26: Op Time (Mins) | D26: — | E26: — | F26: 95 | G26: 95
C27: % Run Time | D27: — | E27: — | F27: 0.24861111 | G27: 0.24861111
C28: % Op Time | D28: — | E28: — | F28: 0.065972222 | G28: 0.065972222
C29: Timed Sessions | F29: 1 | G29: 1
C30: % Timing Coverage | D30: — | E30: — | F30: 1 | G30: 1
C31: Early Start Sessions | F31: 0 | G31: 0
C32: On-Time Start Sessions | F32: 0 | G32: 0
C33: Late Start Sessions | F33: 1 | G33: 1
C34: Early Finish Sessions | F34: 1 | G34: 1
C35: On-Time Finish Sessions | F35: 0 | G35: 0
C36: Late Finish Sessions | F36: 0 | G36: 0
C37: % On-Time Starts | D37: — | E37: — | F37: 0 | G37: 0
C38: % On-Time Finishes | D38: — | E38: — | F38: 0 | G38: 0
B39: Dr Dummy 01 | C39: No. of Sessions | D39: 15 | E39: 15 | F39: 15 | G39: 45
C40: No. of Patients | D40: 60 | E40: 60 | F40: 60 | G40: 180
C41: Planned Time (Mins) | D41: 5130 | E41: 5130 | F41: 5130 | G41: 15390
C42: Planned Time - Timed (Mins) | D42: 5130 | E42: 5130 | F42: 5130 | G42: 15390
C43: Run Time (Mins) | D43: 4589 | E43: 4658 | F43: 4691 | G43: 13938
C44: Op Time (Mins) | D44: 3227 | E44: 3243 | F44: 3359 | G44: 9829
C45: % Run Time | D45: 0.89454191 | E45: 0.9079922 | F45: 0.91442495 | G45: 0.90565302
C46: % Op Time | D46: 0.62904483 | E46: 0.63216374 | F46: 0.65477583 | G46: 0.63866147
C47: Timed Sessions | D47: 15 | E47: 15 | F47: 15 | G47: 45
C48: % Timing Coverage | D48: 1 | E48: 1 | F48: 1 | G48: 1
C49: Early Start Sessions | D49: 0 | E49: 0 | F49: 0 | G49: 0
C50: On-Time Start Sessions | D50: 12 | E50: 12 | F50: 14 | G50: 38
C51: Late Start Sessions | D51: 3 | E51: 3 | F51: 1 | G51: 7
... C56: % On-Time Finishes | D56: 0.066666667 | E56: 0.066666667 | F56: 0 | G56: 0.044444444
B57: Dr Dummy 02 | C57: No. of Sessions | D57: 15 | E57: 15 | F57: 14 | G57: 44
...

Sheet Scheduled Workload
B2: THEATRE UTILISATION — SCHEDULED WORKLOAD
B3: Recorded scheduled patient minutes compared with planned session minutes. This reflects the available extract.
B4: ="Assessed sessions: "&TEXT(GETPIVOTDATA("Assessed Sessions",$B$18),"#,##0")&" / "&TEXT(GETPIVOTDATA("No. of Sessions",$B$18),"#,##0")&". Unassessed: "&TEXT(GETPIVOTDATA("Unassessed Sessions",$B$18),"#,##0")&". 100% compares patient minutes with slot minutes; turnaround and empty allocated lists are not established." -> Assessed sessions: 1,014 / 1,014. Unassessed: 0. 100% compares patient minutes with slot minutes; turnaround and empty allocated lists are not established.
B5: Double-click a value for the contributing sessions. Patient-level drilldown remains on Utilisation - Detail by Theatre. Refresh this pivot after Refresh All finishes.
D18: Financial Year | E18: Month
D19: 26/27 | G19: Total
B20: Session Specialty | C20: Values | D20: 46174 | E20: 46204 | F20: 46235
B21: Emergency Surgery | C21: No. of Sessions | F21: 1 | G21: 1
C22: No. of Patients | F22: 2 | G22: 2
C23: Assessed Sessions | F23: 1 | G23: 1
C24: Unassessed Sessions | F24: 0 | G24: 0
C25: % Workload Coverage | D25: — | E25: — | F25: 1 | G25: 1
C26: Planned Time - Assessed (Mins) | F26: 1440 | G26: 1440
C27: Scheduled Patient Time (Mins) | D27: — | E27: — | F27: 176 | G27: 176
C28: % Recorded Scheduled Load | D28: — | E28: — | F28: 0.12222222 | G28: 0.12222222
C29: Sessions Below 100% Load | F29: 1 | G29: 1
C30: Sessions At 100% Load | F30: 0 | G30: 0
C31: Sessions Above 100% Load | F31: 0 | G31: 0
B32: ENT | C32: No. of Sessions | D32: 39 | E32: 38 | F32: 50 | G32: 127
C33: No. of Patients | D33: 156 | E33: 152 | F33: 200 | G33: 508
C34: Assessed Sessions | D34: 39 | E34: 38 | F34: 50 | G34: 127
C35: Unassessed Sessions | D35: 0 | E35: 0 | F35: 0 | G35: 0
C36: % Workload Coverage | D36: 1 | E36: 1 | F36: 1 | G36: 1
C37: Planned Time - Assessed (Mins) | D37: 12930 | E37: 12390 | F37: 17490 | G37: 42810
C38: Scheduled Patient Time (Mins) | D38: 8000 | E38: 7555 | F38: 11240 | G38: 26795
C39: % Recorded Scheduled Load | D39: 0.61871616 | E39: 0.60976594 | F39: 0.64265294 | G39: 0.62590516
C40: Sessions Below 100% Load | D40: 39 | E40: 38 | F40: 50 | G40: 127
C41: Sessions At 100% Load | D41: 0 | E41: 0 | F41: 0 | G41: 0
C42: Sessions Above 100% Load | D42: 0 | E42: 0 | F42: 0 | G42: 0
B43: General Surgery | C43: No. of Sessions | D43: 45 | E43: 45 | F43: 45 | G43: 135
C44: No. of Patients | D44: 180 | E44: 180 | F44: 180 | G44: 540
C45: Assessed Sessions | D45: 45 | E45: 45 | F45: 45 | G45: 135
C46: Unassessed Sessions | D46: 0 | E46: 0 | F46: 0 | G46: 0
C47: % Workload Coverage | D47: 1 | E47: 1 | F47: 1 | G47: 1
C48: Planned Time - Assessed (Mins) | D48: 16620 | E48: 15600 | F48: 15810 | G48: 48030
C49: Scheduled Patient Time (Mins) | D49: 10650 | E49: 10075 | F49: 10020 | G49: 30745
C50: % Recorded Scheduled Load | D50: 0.64079422 | E50: 0.64583333 | F50: 0.63377609 | G50: 0.64012076
C51: Sessions Below 100% Load | D51: 45 | E51: 45 | F51: 45 | G51: 135
C52: Sessions At 100% Load | D52: 0 | E52: 0 | F52: 0 | G52: 0
C53: Sessions Above 100% Load | D53: 0 | E53: 0 | F53: 0 | G53: 0
...

Sheet Weekly Review
B2: THEATRE UTILISATION — SEVEN-DAY REVIEW
B3: ="Review period: "&TEXT(WeeklyStart,"dd mmm yyyy")&" to "&TEXT(WeeklyEnd,"dd mmm yyyy")&IF('Weekly Review'!E19=""," (previous seven completed days)"," (historical date selected)") -> Review period: 25 Aug 2026 to 31 Aug 2026 (historical date selected)
B4: ="Latest recorded activity: "&TEXT(Setup!V4,"dd mmm yyyy")&". "&IF(Setup!V4<WeeklyEnd,"Extracts do not reach the end of this review period. ","")&IF(TODAY()-1>Setup!V4,TEXT(TODAY()-1-Setup!V4,"0")&" completed days since that date. ","")&"A recorded date does not prove complete capture." -> Latest recorded activity: 31 Aug 2026. 57 completed days since that date. A recorded date does not prove complete capture.
B5: Slicers are shared by these two tabs and filter Review Data. Existing report pivots keep their own selections.
B6: Run/op rates use matched complete-timing sessions. On Time includes ±10 minutes. Responsible consultant is the recorded list owner.
B19: Historical week ending | E19: 46265 | G19: Clear the yellow date for the seven completed days ending yesterday.
B22: Sessions | E22: Patient encounters | H22: Planned time (mins) | K22: Run utilisation | N22: Op utilisation
B23: =Setup!V5 -> 76 | E23: =Setup!V7 -> 304 | H23: =Setup!V8 -> 26100 | K23: =Setup!V22 -> 0.90954023 | N23: =Setup!V23 -> 0.62896552
B25: Timing coverage | E25: Late start sessions | H25: Late finish sessions | K25: Patients excluded: times | N25: Recorded scheduled load
B26: =Setup!V24 -> 1 | E26: =Setup!V12 -> 13 | H26: =Setup!V13 -> 0 | K26: =Setup!V18 -> 0 | N26: =Setup!V25 -> 0.62643678
B28: ="Timed sessions: "&Setup!V6&" / "&Setup!V5&". Scheduled-workload coverage: "&TEXT(Setup!V26,"0.0%")&". Missing-time patients are excluded from the patient count; represented sessions remain included." -> Timed sessions: 76 / 76. Scheduled-workload coverage: 100.0%. Missing-time patients are excluded from the patient count; represented sessions remain included.
B29: Date | C29: Sessions | D29: Patients | E29: Planned mins | F29: Timed planned mins | G29: Run mins | H29: Op mins | I29: Run % | J29: Op % | K29: Late starts | L29: Late finishes | M29: Timed sessions | N29: Recorded activity
B30: =WeeklyStart+0 -> 46259 | C30: =SUMPRODUCT(WeeklyMask,--(SessionReviewTable[Procedure Date]=$B30),SessionReviewTable[No of Sessions]) -> 9 | D30: =SUMPRODUCT(WeeklyMask,--(SessionReviewTable[Procedure Date]=$B30),SessionReviewTable[No of Patients]) -> 36 | E30: =SUMPRODUCT(WeeklyMask,--(SessionReviewTable[Procedure Date]=$B30),SessionReviewTable[Session Duration]) -> 3510 | F30: =SUMPRODUCT(WeeklyMask,--(SessionReviewTable[Procedure Date]=$B30),SessionReviewTable[Session Duration Used for Timing]) -> 3510 | G30: =SUMPRODUCT(WeeklyMask,--(SessionReviewTable[Procedure Date]=$B30),SessionReviewTable[Run Minutes]) -> 3252 | H30: =SUMPRODUCT(WeeklyMask,--(SessionReviewTable[Procedure Date]=$B30),SessionReviewTable[Op Minutes]) -> 2279 | I30: =IF(F30=0,"—",G30/F30) -> 0.92649573 | J30: =IF(F30=0,"—",H30/F30) -> 0.64928775 | K30: =SUMPRODUCT(WeeklyMask,--(SessionReviewTable[Procedure Date]=$B30),SessionReviewTable[Late Starts]) -> 3 | L30: =SUMPRODUCT(WeeklyMask,--(SessionReviewTable[Procedure Date]=$B30),SessionReviewTable[Late Finishes]) -> 0 | M30: =SUMPRODUCT(WeeklyMask,--(SessionReviewTable[Procedure Date]=$B30),SessionReviewTable[Sessions Used for Timing]) -> 9 | N30: =IF(C30=0,"No recorded activity",IF(M30<C30,"Timing incomplete","Activity recorded")) -> Activity recorded
B31: =WeeklyStart+1 -> 46260 | C31: =SUMPRODUCT(WeeklyMask,--(SessionReviewTable[Procedure Date]=$B31),SessionReviewTable[No of Sessions]) -> 13 | D31: =SUMPRODUCT(WeeklyMask,--(SessionReviewTable[Procedure Date]=$B31),SessionReviewTable[No of Patients]) -> 52 | E31: =SUMPRODUCT(WeeklyMask,--(SessionReviewTable[Procedure Date]=$B31),SessionReviewTable[Session Duration]) -> 4380 | F31: =SUMPRODUCT(WeeklyMask,--(SessionReviewTable[Procedure Date]=$B31),SessionReviewTable[Session Duration Used for Timing]) -> 4380 | G31: =SUMPRODUCT(WeeklyMask,--(SessionReviewTable[Procedure Date]=$B31),SessionReviewTable[Run Minutes]) -> 3929 | H31: =SUMPRODUCT(WeeklyMask,--(SessionReviewTable[Procedure Date]=$B31),SessionReviewTable[Op Minutes]) -> 2711 | I31: =IF(F31=0,"—",G31/F31) -> 0.89703196 | J31: =IF(F31=0,"—",H31/F31) -> 0.61894977 | K31: =SUMPRODUCT(WeeklyMask,--(SessionReviewTable[Procedure Date]=$B31),SessionReviewTable[Late Starts]) -> 0 | L31: =SUMPRODUCT(WeeklyMask,--(SessionReviewTable[Procedure Date]=$B31),SessionReviewTable[Late Finishes]) -> 0 | M31: =SUMPRODUCT(WeeklyMask,--(SessionReviewTable[Procedure Date]=$B31),SessionReviewTable[Sessions Used for Timing]) -> 13 | N31: =IF(C31=0,"No recorded activity",IF(M31<C31,"Timing incomplete","Activity recorded")) -> Activity recorded
B32: =WeeklyStart+2 -> 46261 | C32: =SUMPRODUCT(WeeklyMask,--(SessionReviewTable[Procedure Date]=$B32),SessionReviewTable[No of Sessions]) -> 10 | D32: =SUMPRODUCT(WeeklyMask,--(SessionReviewTable[Procedure Date]=$B32),SessionReviewTable[No of Patients]) -> 40 | E32: =SUMPRODUCT(WeeklyMask,--(SessionReviewTable[Procedure Date]=$B32),SessionReviewTable[Session Duration]) -> 3060 | F32: =SUMPRODUCT(WeeklyMask,--(SessionReviewTable[Procedure Date]=$B32),SessionReviewTable[Session Duration Used for Timing]) -> 3060 | G32: =SUMPRODUCT(WeeklyMask,--(SessionReviewTable[Procedure Date]=$B32),SessionReviewTable[Run Minutes]) -> 2814 | H32: =SUMPRODUCT(WeeklyMask,--(SessionReviewTable[Procedure Date]=$B32),SessionReviewTable[Op Minutes]) -> 1943 | I32: =IF(F32=0,"—",G32/F32) -> 0.91960784 | J32: =IF(F32=0,"—",H32/F32) -> 0.63496732 | K32: =SUMPRODUCT(WeeklyMask,--(SessionReviewTable[Procedure Date]=$B32),SessionReviewTable[Late Starts]) -> 1 | L32: =SUMPRODUCT(WeeklyMask,--(SessionReviewTable[Procedure Date]=$B32),SessionReviewTable[Late Finishes]) -> 0 | M32: =SUMPRODUCT(WeeklyMask,--(SessionReviewTable[Procedure Date]=$B32),SessionReviewTable[Sessions Used for Timing]) -> 10 | N32: =IF(C32=0,"No recorded activity",IF(M32<C32,"Timing incomplete","Activity recorded")) -> Activity recorded
B33: =WeeklyStart+3 -> 46262 | C33: =SUMPRODUCT(WeeklyMask,--(SessionReviewTable[Procedure Date]=$B33),SessionReviewTable[No of Sessions]) -> 12 | D33: =SUMPRODUCT(WeeklyMask,--(SessionReviewTable[Procedure Date]=$B33),SessionReviewTable[No of Patients]) -> 48 | E33: =SUMPRODUCT(WeeklyMask,--(SessionReviewTable[Procedure Date]=$B33),SessionReviewTable[Session Duration]) -> 4110 | F33: =SUMPRODUCT(WeeklyMask,--(SessionReviewTable[Procedure Date]=$B33),SessionReviewTable[Session Duration Used for Timing]) -> 4110 | G33: =SUMPRODUCT(WeeklyMask,--(SessionReviewTable[Procedure Date]=$B33),SessionReviewTable[Run Minutes]) -> 3748 | H33: =SUMPRODUCT(WeeklyMask,--(SessionReviewTable[Procedure Date]=$B33),SessionReviewTable[Op Minutes]) -> 2619 | I33: =IF(F33=0,"—",G33/F33) -> 0.91192214 | J33: =IF(F33=0,"—",H33/F33) -> 0.63722628 | K33: =SUMPRODUCT(WeeklyMask,--(SessionReviewTable[Procedure Date]=$B33),SessionReviewTable[Late Starts]) -> 3 | L33: =SUMPRODUCT(WeeklyMask,--(SessionReviewTable[Procedure Date]=$B33),SessionReviewTable[Late Finishes]) -> 0 | M33: =SUMPRODUCT(WeeklyMask,--(SessionReviewTable[Procedure Date]=$B33),SessionReviewTable[Sessions Used for Timing]) -> 12 | N33: =IF(C33=0,"No recorded activity",IF(M33<C33,"Timing incomplete","Activity recorded")) -> Activity recorded
B34: =WeeklyStart+4 -> 46263 | C34: =SUMPRODUCT(WeeklyMask,--(SessionReviewTable[Procedure Date]=$B34),SessionReviewTable[No of Sessions]) -> 11 | D34: =SUMPRODUCT(WeeklyMask,--(SessionReviewTable[Procedure Date]=$B34),SessionReviewTable[No of Patients]) -> 44 | E34: =SUMPRODUCT(WeeklyMask,--(SessionReviewTable[Procedure Date]=$B34),SessionReviewTable[Session Duration]) -> 3720 | F34: =SUMPRODUCT(WeeklyMask,--(SessionReviewTable[Procedure Date]=$B34),SessionReviewTable[Session Duration Used for Timing]) -> 3720 | G34: =SUMPRODUCT(WeeklyMask,--(SessionReviewTable[Procedure Date]=$B34),SessionReviewTable[Run Minutes]) -> 3373 | H34: =SUMPRODUCT(WeeklyMask,--(SessionReviewTable[Procedure Date]=$B34),SessionReviewTable[Op Minutes]) -> 2333 | I34: =IF(F34=0,"—",G34/F34) -> 0.90672043 | J34: =IF(F34=0,"—",H34/F34) -> 0.62715054 | K34: =SUMPRODUCT(WeeklyMask,--(SessionReviewTable[Procedure Date]=$B34),SessionReviewTable[Late Starts]) -> 3 | L34: =SUMPRODUCT(WeeklyMask,--(SessionReviewTable[Procedure Date]=$B34),SessionReviewTable[Late Finishes]) -> 0 | M34: =SUMPRODUCT(WeeklyMask,--(SessionReviewTable[Procedure Date]=$B34),SessionReviewTable[Sessions Used for Timing]) -> 11 | N34: =IF(C34=0,"No recorded activity",IF(M34<C34,"Timing incomplete","Activity recorded")) -> Activity recorded
B35: =WeeklyStart+5 -> 46264 | C35: =SUMPRODUCT(WeeklyMask,--(SessionReviewTable[Procedure Date]=$B35),SessionReviewTable[No of Sessions]) -> 11 | D35: =SUMPRODUCT(WeeklyMask,--(SessionReviewTable[Procedure Date]=$B35),SessionReviewTable[No of Patients]) -> 44 | E35: =SUMPRODUCT(WeeklyMask,--(SessionReviewTable[Procedure Date]=$B35),SessionReviewTable[Session Duration]) -> 3600 | F35: =SUMPRODUCT(WeeklyMask,--(SessionReviewTable[Procedure Date]=$B35),SessionReviewTable[Session Duration Used for Timing]) -> 3600 | G35: =SUMPRODUCT(WeeklyMask,--(SessionReviewTable[Procedure Date]=$B35),SessionReviewTable[Run Minutes]) -> 3240 | H35: =SUMPRODUCT(WeeklyMask,--(SessionReviewTable[Procedure Date]=$B35),SessionReviewTable[Op Minutes]) -> 2169 | I35: =IF(F35=0,"—",G35/F35) -> 0.9 | J35: =IF(F35=0,"—",H35/F35) -> 0.6025 | K35: =SUMPRODUCT(WeeklyMask,--(SessionReviewTable[Procedure Date]=$B35),SessionReviewTable[Late Starts]) -> 2 | L35: =SUMPRODUCT(WeeklyMask,--(SessionReviewTable[Procedure Date]=$B35),SessionReviewTable[Late Finishes]) -> 0 | M35: =SUMPRODUCT(WeeklyMask,--(SessionReviewTable[Procedure Date]=$B35),SessionReviewTable[Sessions Used for Timing]) -> 11 | N35: =IF(C35=0,"No recorded activity",IF(M35<C35,"Timing incomplete","Activity recorded")) -> Activity recorded
B36: =WeeklyStart+6 -> 46265 | C36: =SUMPRODUCT(WeeklyMask,--(SessionReviewTable[Procedure Date]=$B36),SessionReviewTable[No of Sessions]) -> 10 | D36: =SUMPRODUCT(WeeklyMask,--(SessionReviewTable[Procedure Date]=$B36),SessionReviewTable[No of Patients]) -> 40 | E36: =SUMPRODUCT(WeeklyMask,--(SessionReviewTable[Procedure Date]=$B36),SessionReviewTable[Session Duration]) -> 3720 | F36: =SUMPRODUCT(WeeklyMask,--(SessionReviewTable[Procedure Date]=$B36),SessionReviewTable[Session Duration Used for Timing]) -> 3720 | G36: =SUMPRODUCT(WeeklyMask,--(SessionReviewTable[Procedure Date]=$B36),SessionReviewTable[Run Minutes]) -> 3383 | H36: =SUMPRODUCT(WeeklyMask,--(SessionReviewTable[Procedure Date]=$B36),SessionReviewTable[Op Minutes]) -> 2362 | I36: =IF(F36=0,"—",G36/F36) -> 0.9094086 | J36: =IF(F36=0,"—",H36/F36) -> 0.63494624 | K36: =SUMPRODUCT(WeeklyMask,--(SessionReviewTable[Procedure Date]=$B36),SessionReviewTable[Late Starts]) -> 1 | L36: =SUMPRODUCT(WeeklyMask,--(SessionReviewTable[Procedure Date]=$B36),SessionReviewTable[Late Finishes]) -> 0 | M36: =SUMPRODUCT(WeeklyMask,--(SessionReviewTable[Procedure Date]=$B36),SessionReviewTable[Sessions Used for Timing]) -> 10 | N36: =IF(C36=0,"No recorded activity",IF(M36<C36,"Timing incomplete","Activity recorded")) -> Activity recorded
B37: Total | C37: =SUM(C30:C36) -> 76 | D37: =SUM(D30:D36) -> 304 | E37: =SUM(E30:E36) -> 26100 | F37: =SUM(F30:F36) -> 26100 | G37: =SUM(G30:G36) -> 23739 | H37: =SUM(H30:H36) -> 16416 | I37: =IF(F37=0,"—",G37/F37) -> 0.90954023 | J37: =IF(F37=0,"—",H37/F37) -> 0.62896552 | K37: =SUM(K30:K36) -> 13 | L37: =SUM(L30:L36) -> 0 | M37: =SUM(M30:M36) -> 76
B52: Session punctuality | J52: Scheduled workload and coverage
B53: Classification | C53: Start | D53: Finish | J53: Assessed sessions | O53: =Setup!V19 -> 76
B54: Early | C54: =Setup!V14 -> 0 | D54: =Setup!V16 -> 72 | J54: Scheduled patient minutes | O54: =Setup!V21 -> 16350
B55: On Time | C55: =Setup!V15 -> 63 | D55: =Setup!V17 -> 4 | J55: Assessed planned minutes | O55: =Setup!V20 -> 26100
B56: Late | C56: =Setup!V12 -> 13 | D56: =Setup!V13 -> 0 | J56: Workload coverage | O56: =Setup!V26 -> 1
B57: Unclassified | C57: =Setup!V27 -> 0 | D57: =Setup!V27 -> 0
B59: Recorded scheduled load compares supplied patient minutes with planned minutes for assessed sessions. It does not establish spare booking capacity.
B60: Use Session Timeline to compare planned and actual spans, inspect exact times, and review timing notes for each selected session.
B61: Open Session Timeline

Sheet Session Timeline
B2: THEATRE UTILISATION — SESSION TIMELINE
B3: ="Review period: "&TEXT(WeeklyStart,"dd mmm yyyy")&" to "&TEXT(WeeklyEnd,"dd mmm yyyy")&IF('Weekly Review'!E19=""," (previous seven completed days)"," (historical date selected)") -> Review period: 25 Aug 2026 to 31 Aug 2026 (historical date selected)
B4: ="Latest recorded activity: "&TEXT(Setup!V4,"dd mmm yyyy")&". "&IF(Setup!V4<WeeklyEnd,"Extracts do not reach the end of this review period. ","")&IF(TODAY()-1>Setup!V4,TEXT(TODAY()-1-Setup!V4,"0")&" completed days since that date. ","")&"A recorded date does not prove complete capture." -> Latest recorded activity: 31 Aug 2026. 57 completed days since that date. A recorded date does not prove complete capture.
B5: Slicers are shared by these two tabs and filter Review Data. Existing report pivots keep their own selections.
B6: Run/op rates use matched complete-timing sessions. On Time includes ±10 minutes. Responsible consultant is the recorded list owner.
B19: Timeline page | E19: 1 | F19: =IF(Setup!V30,"Page "&Setup!V29&" of "&Setup!V28&". 12 sessions per page, ordered by date. Edit the yellow page number to continue.","Enter a whole page number of 1 or more. Page 1 is shown until corrected.") -> Page 1 of 7. 12 sessions per page, ordered by date. Edit the yellow page number to continue.
B20: =IF(Setup!V5=0,"No recorded sessions match this period and these filters.","Showing sessions "&((Setup!V29-1)*12+1)&"–"&MIN(Setup!V29*12,Setup!V5)&" of "&Setup!V5&" selected sessions. Filter by theatre or specialty for a focused review.") -> Showing sessions 1–12 of 76 selected sessions. Filter by theatre or specialty for a focused review.
B21: Planned = green. Actual run = blue, including gaps. Op minutes are separate totals, not continuous clock-time bars.
B22: Each row starts at midnight on its labelled date. 24:00 means the next day. Invalid actual timing has no blue bar.
B51: Session details for this page — full-second timing is retained in the source; minutes below show one decimal.
B52: Date | C52: Theatre | D52: Specialty | E52: Consultant | F52: Planned start | G52: Planned end | H52: Actual start | I52: Actual end | J52: Patients | K52: Run mins | L52: Op mins | M52: Start type | N52: Finish type | O52: Timing notes | P52: Patients excluded | Q52: Scheduling notes
B53: =IF(Setup!$U46="","",IF(INDEX(SessionReviewTable[Procedure Date],Setup!$U46)="","",INDEX(SessionReviewTable[Procedure Date],Setup!$U46))) -> 46259 | C53: =IF(Setup!$U46="","",IF(INDEX(SessionReviewTable[Operating Theatre],Setup!$U46)="","",INDEX(SessionReviewTable[Operating Theatre],Setup!$U46))) -> ST CAH MAIN THEATRE 7 | D53: =IF(Setup!$U46="","",IF(INDEX(SessionReviewTable[Session Specialty],Setup!$U46)="","",INDEX(SessionReviewTable[Session Specialty],Setup!$U46))) -> General Surgery | E53: =IF(Setup!$U46="","",IF(INDEX(SessionReviewTable[Responsible Consultant],Setup!$U46)="","",INDEX(SessionReviewTable[Responsible Consultant],Setup!$U46))) -> Dr Dummy 03 | F53: =IF(Setup!$U46="","",IF(INDEX(SessionReviewTable[Slot Start Time],Setup!$U46)="","",INDEX(SessionReviewTable[Slot Start Time],Setup!$U46))) -> 46259.312 | G53: =IF(Setup!$U46="","",IF(INDEX(SessionReviewTable[Slot End Time],Setup!$U46)="","",INDEX(SessionReviewTable[Slot End Time],Setup!$U46))) -> 46259.688 | H53: =IF(Setup!$U46="","",IF(INDEX(SessionReviewTable[First Actual Start],Setup!$U46)="","",INDEX(SessionReviewTable[First Actual Start],Setup!$U46))) -> 46259.316 | I53: =IF(Setup!$U46="","",IF(INDEX(SessionReviewTable[Last Actual End],Setup!$U46)="","",INDEX(SessionReviewTable[Last Actual End],Setup!$U46))) -> 46259.661 | J53: =IF(Setup!$U46="","",IF(INDEX(SessionReviewTable[No of Patients],Setup!$U46)="","",INDEX(SessionReviewTable[No of Patients],Setup!$U46))) -> 4 | K53: =IF(Setup!$U46="","",IF(INDEX(SessionReviewTable[Run Minutes],Setup!$U46)="","",INDEX(SessionReviewTable[Run Minutes],Setup!$U46))) -> 497 | L53: =IF(Setup!$U46="","",IF(INDEX(SessionReviewTable[Op Minutes],Setup!$U46)="","",INDEX(SessionReviewTable[Op Minutes],Setup!$U46))) -> 375 | M53: =IF(Setup!$U46="","",IF(INDEX(SessionReviewTable[Start Type],Setup!$U46)="","",INDEX(SessionReviewTable[Start Type],Setup!$U46))) -> On Time | N53: =IF(Setup!$U46="","",IF(INDEX(SessionReviewTable[Finish Type],Setup!$U46)="","",INDEX(SessionReviewTable[Finish Type],Setup!$U46))) -> Early Finish | O53: =IF(Setup!$U46="","",IF(INDEX(SessionReviewTable[Timing Notes],Setup!$U46)="","None",HYPERLINK("#'Review Data'!AD"&(Setup!$U46+5),"Open notes"))) -> None | P53: =IF(Setup!$U46="","",IF(INDEX(SessionReviewTable[Patients Excluded - Missing Times],Setup!$U46)="","",INDEX(SessionReviewTable[Patients Excluded - Missing Times],Setup!$U46))) -> 0 | Q53: =IF(Setup!$U46="","",IF(INDEX(SessionReviewTable[Scheduling Notes],Setup!$U46)="","None",HYPERLINK("#'Review Data'!BH"&(Setup!$U46+5),"Open notes"))) -> None
B54: =IF(Setup!$U47="","",IF(INDEX(SessionReviewTable[Procedure Date],Setup!$U47)="","",INDEX(SessionReviewTable[Procedure Date],Setup!$U47))) -> 46259 | C54: =IF(Setup!$U47="","",IF(INDEX(SessionReviewTable[Operating Theatre],Setup!$U47)="","",INDEX(SessionReviewTable[Operating Theatre],Setup!$U47))) -> ST CAH MAIN THEATRE 3 | D54: =IF(Setup!$U47="","",IF(INDEX(SessionReviewTable[Session Specialty],Setup!$U47)="","",INDEX(SessionReviewTable[Session Specialty],Setup!$U47))) -> Gynaecology | E54: =IF(Setup!$U47="","",IF(INDEX(SessionReviewTable[Responsible Consultant],Setup!$U47)="","",INDEX(SessionReviewTable[Responsible Consultant],Setup!$U47))) -> Dr Dummy 09 | F54: =IF(Setup!$U47="","",IF(INDEX(SessionReviewTable[Slot Start Time],Setup!$U47)="","",INDEX(SessionReviewTable[Slot Start Time],Setup!$U47))) -> 46259.312 | G54: =IF(Setup!$U47="","",IF(INDEX(SessionReviewTable[Slot End Time],Setup!$U47)="","",INDEX(SessionReviewTable[Slot End Time],Setup!$U47))) -> 46259.646 | H54: =IF(Setup!$U47="","",IF(INDEX(SessionReviewTable[First Actual Start],Setup!$U47)="","",INDEX(SessionReviewTable[First Actual Start],Setup!$U47))) -> 46259.321 | I54: =IF(Setup!$U47="","",IF(INDEX(SessionReviewTable[Last Actual End],Setup!$U47)="","",INDEX(SessionReviewTable[Last Actual End],Setup!$U47))) -> 46259.623 | J54: =IF(Setup!$U47="","",IF(INDEX(SessionReviewTable[No of Patients],Setup!$U47)="","",INDEX(SessionReviewTable[No of Patients],Setup!$U47))) -> 4 | K54: =IF(Setup!$U47="","",IF(INDEX(SessionReviewTable[Run Minutes],Setup!$U47)="","",INDEX(SessionReviewTable[Run Minutes],Setup!$U47))) -> 435 | L54: =IF(Setup!$U47="","",IF(INDEX(SessionReviewTable[Op Minutes],Setup!$U47)="","",INDEX(SessionReviewTable[Op Minutes],Setup!$U47))) -> 317 | M54: =IF(Setup!$U47="","",IF(INDEX(SessionReviewTable[Start Type],Setup!$U47)="","",INDEX(SessionReviewTable[Start Type],Setup!$U47))) -> Late Start | N54: =IF(Setup!$U47="","",IF(INDEX(SessionReviewTable[Finish Type],Setup!$U47)="","",INDEX(SessionReviewTable[Finish Type],Setup!$U47))) -> Early Finish | O54: =IF(Setup!$U47="","",IF(INDEX(SessionReviewTable[Timing Notes],Setup!$U47)="","None",HYPERLINK("#'Review Data'!AD"&(Setup!$U47+5),"Open notes"))) -> None | P54: =IF(Setup!$U47="","",IF(INDEX(SessionReviewTable[Patients Excluded - Missing Times],Setup!$U47)="","",INDEX(SessionReviewTable[Patients Excluded - Missing Times],Setup!$U47))) -> 0 | Q54: =IF(Setup!$U47="","",IF(INDEX(SessionReviewTable[Scheduling Notes],Setup!$U47)="","None",HYPERLINK("#'Review Data'!BH"&(Setup!$U47+5),"Open notes"))) -> None
B55: =IF(Setup!$U48="","",IF(INDEX(SessionReviewTable[Procedure Date],Setup!$U48)="","",INDEX(SessionReviewTable[Procedure Date],Setup!$U48))) -> 46259 | C55: =IF(Setup!$U48="","",IF(INDEX(SessionReviewTable[Operating Theatre],Setup!$U48)="","",INDEX(SessionReviewTable[Operating Theatre],Setup!$U48))) -> ST CAH MAIN THEATRE 2 | D55: =IF(Setup!$U48="","",IF(INDEX(SessionReviewTable[Session Specialty],Setup!$U48)="","",INDEX(SessionReviewTable[Session Specialty],Setup!$U48))) -> Gynaecology | E55: =IF(Setup!$U48="","",IF(INDEX(SessionReviewTable[Responsible Consultant],Setup!$U48)="","",INDEX(SessionReviewTable[Responsible Consultant],Setup!$U48))) -> Dr Dummy 12 | F55: =IF(Setup!$U48="","",IF(INDEX(SessionReviewTable[Slot Start Time],Setup!$U48)="","",INDEX(SessionReviewTable[Slot Start Time],Setup!$U48))) -> 46259.312 | G55: =IF(Setup!$U48="","",IF(INDEX(SessionReviewTable[Slot End Time],Setup!$U48)="","",INDEX(SessionReviewTable[Slot End Time],Setup!$U48))) -> 46259.604 | H55: =IF(Setup!$U48="","",IF(INDEX(SessionReviewTable[First Actual Start],Setup!$U48)="","",INDEX(SessionReviewTable[First Actual Start],Setup!$U48))) -> 46259.321 | I55: =IF(Setup!$U48="","",IF(INDEX(SessionReviewTable[Last Actual End],Setup!$U48)="","",INDEX(SessionReviewTable[Last Actual End],Setup!$U48))) -> 46259.593 | J55: =IF(Setup!$U48="","",IF(INDEX(SessionReviewTable[No of Patients],Setup!$U48)="","",INDEX(SessionReviewTable[No of Patients],Setup!$U48))) -> 4 | K55: =IF(Setup!$U48="","",IF(INDEX(SessionReviewTable[Run Minutes],Setup!$U48)="","",INDEX(SessionReviewTable[Run Minutes],Setup!$U48))) -> 392 | L55: =IF(Setup!$U48="","",IF(INDEX(SessionReviewTable[Op Minutes],Setup!$U48)="","",INDEX(SessionReviewTable[Op Minutes],Setup!$U48))) -> 292 | M55: =IF(Setup!$U48="","",IF(INDEX(SessionReviewTable[Start Type],Setup!$U48)="","",INDEX(SessionReviewTable[Start Type],Setup!$U48))) -> Late Start | N55: =IF(Setup!$U48="","",IF(INDEX(SessionReviewTable[Finish Type],Setup!$U48)="","",INDEX(SessionReviewTable[Finish Type],Setup!$U48))) -> Early Finish | O55: =IF(Setup!$U48="","",IF(INDEX(SessionReviewTable[Timing Notes],Setup!$U48)="","None",HYPERLINK("#'Review Data'!AD"&(Setup!$U48+5),"Open notes"))) -> None | P55: =IF(Setup!$U48="","",IF(INDEX(SessionReviewTable[Patients Excluded - Missing Times],Setup!$U48)="","",INDEX(SessionReviewTable[Patients Excluded - Missing Times],Setup!$U48))) -> 0 | Q55: =IF(Setup!$U48="","",IF(INDEX(SessionReviewTable[Scheduling Notes],Setup!$U48)="","None",HYPERLINK("#'Review Data'!BH"&(Setup!$U48+5),"Open notes"))) -> None
B56: =IF(Setup!$U49="","",IF(INDEX(SessionReviewTable[Procedure Date],Setup!$U49)="","",INDEX(SessionReviewTable[Procedure Date],Setup!$U49))) -> 46259 | C56: =IF(Setup!$U49="","",IF(INDEX(SessionReviewTable[Operating Theatre],Setup!$U49)="","",INDEX(SessionReviewTable[Operating Theatre],Setup!$U49))) -> ST CAH MAIN THEATRE 1 | D56: =IF(Setup!$U49="","",IF(INDEX(SessionReviewTable[Session Specialty],Setup!$U49)="","",INDEX(SessionReviewTable[Session Specialty],Setup!$U49))) -> Urology | E56: =IF(Setup!$U49="","",IF(INDEX(SessionReviewTable[Responsible Consultant],Setup!$U49)="","",INDEX(SessionReviewTable[Responsible Consultant],Setup!$U49))) -> Dr Dummy 24 | F56: =IF(Setup!$U49="","",IF(INDEX(SessionReviewTable[Slot Start Time],Setup!$U49)="","",INDEX(SessionReviewTable[Slot Start Time],Setup!$U49))) -> 46259.354 | G56: =IF(Setup!$U49="","",IF(INDEX(SessionReviewTable[Slot End Time],Setup!$U49)="","",INDEX(SessionReviewTable[Slot End Time],Setup!$U49))) -> 46259.729 | H56: =IF(Setup!$U49="","",IF(INDEX(SessionReviewTable[First Actual Start],Setup!$U49)="","",INDEX(SessionReviewTable[First Actual Start],Setup!$U49))) -> 46259.356 | I56: =IF(Setup!$U49="","",IF(INDEX(SessionReviewTable[Last Actual End],Setup!$U49)="","",INDEX(SessionReviewTable[Last Actual End],Setup!$U49))) -> 46259.713 | J56: =IF(Setup!$U49="","",IF(INDEX(SessionReviewTable[No of Patients],Setup!$U49)="","",INDEX(SessionReviewTable[No of Patients],Setup!$U49))) -> 4 | K56: =IF(Setup!$U49="","",IF(INDEX(SessionReviewTable[Run Minutes],Setup!$U49)="","",INDEX(SessionReviewTable[Run Minutes],Setup!$U49))) -> 515 | L56: =IF(Setup!$U49="","",IF(INDEX(SessionReviewTable[Op Minutes],Setup!$U49)="","",INDEX(SessionReviewTable[Op Minutes],Setup!$U49))) -> 400 | M56: =IF(Setup!$U49="","",IF(INDEX(SessionReviewTable[Start Type],Setup!$U49)="","",INDEX(SessionReviewTable[Start Type],Setup!$U49))) -> On Time | N56: =IF(Setup!$U49="","",IF(INDEX(SessionReviewTable[Finish Type],Setup!$U49)="","",INDEX(SessionReviewTable[Finish Type],Setup!$U49))) -> Early Finish | O56: =IF(Setup!$U49="","",IF(INDEX(SessionReviewTable[Timing Notes],Setup!$U49)="","None",HYPERLINK("#'Review Data'!AD"&(Setup!$U49+5),"Open notes"))) -> None | P56: =IF(Setup!$U49="","",IF(INDEX(SessionReviewTable[Patients Excluded - Missing Times],Setup!$U49)="","",INDEX(SessionReviewTable[Patients Excluded - Missing Times],Setup!$U49))) -> 0 | Q56: =IF(Setup!$U49="","",IF(INDEX(SessionReviewTable[Scheduling Notes],Setup!$U49)="","None",HYPERLINK("#'Review Data'!BH"&(Setup!$U49+5),"Open notes"))) -> None
B57: =IF(Setup!$U50="","",IF(INDEX(SessionReviewTable[Procedure Date],Setup!$U50)="","",INDEX(SessionReviewTable[Procedure Date],Setup!$U50))) -> 46259 | C57: =IF(Setup!$U50="","",IF(INDEX(SessionReviewTable[Operating Theatre],Setup!$U50)="","",INDEX(SessionReviewTable[Operating Theatre],Setup!$U50))) -> ST DHH MAIN THEATRE 3 | D57: =IF(Setup!$U50="","",IF(INDEX(SessionReviewTable[Session Specialty],Setup!$U50)="","",INDEX(SessionReviewTable[Session Specialty],Setup!$U50))) -> ENT | E57: =IF(Setup!$U50="","",IF(INDEX(SessionReviewTable[Responsible Consultant],Setup!$U50)="","",INDEX(SessionReviewTable[Responsible Consultant],Setup!$U50))) -> Dr Dummy 22 | F57: =IF(Setup!$U50="","",IF(INDEX(SessionReviewTable[Slot Start Time],Setup!$U50)="","",INDEX(SessionReviewTable[Slot Start Time],Setup!$U50))) -> 46259.562 | G57: =IF(Setup!$U50="","",IF(INDEX(SessionReviewTable[Slot End Time],Setup!$U50)="","",INDEX(SessionReviewTable[Slot End Time],Setup!$U50))) -> 46259.75 | H57: =IF(Setup!$U50="","",IF(INDEX(SessionReviewTable[First Actual Start],Setup!$U50)="","",INDEX(SessionReviewTable[First Actual Start],Setup!$U50))) -> 46259.564 | I57: =IF(Setup!$U50="","",IF(INDEX(SessionReviewTable[Last Actual End],Setup!$U50)="","",INDEX(SessionReviewTable[Last Actual End],Setup!$U50))) -> 46259.74 | J57: =IF(Setup!$U50="","",IF(INDEX(SessionReviewTable[No of Patients],Setup!$U50)="","",INDEX(SessionReviewTable[No of Patients],Setup!$U50))) -> 4 | K57: =IF(Setup!$U50="","",IF(INDEX(SessionReviewTable[Run Minutes],Setup!$U50)="","",INDEX(SessionReviewTable[Run Minutes],Setup!$U50))) -> 254 | L57: =IF(Setup!$U50="","",IF(INDEX(SessionReviewTable[Op Minutes],Setup!$U50)="","",INDEX(SessionReviewTable[Op Minutes],Setup!$U50))) -> 153 | M57: =IF(Setup!$U50="","",IF(INDEX(SessionReviewTable[Start Type],Setup!$U50)="","",INDEX(SessionReviewTable[Start Type],Setup!$U50))) -> On Time | N57: =IF(Setup!$U50="","",IF(INDEX(SessionReviewTable[Finish Type],Setup!$U50)="","",INDEX(SessionReviewTable[Finish Type],Setup!$U50))) -> Early Finish | O57: =IF(Setup!$U50="","",IF(INDEX(SessionReviewTable[Timing Notes],Setup!$U50)="","None",HYPERLINK("#'Review Data'!AD"&(Setup!$U50+5),"Open notes"))) -> None | P57: =IF(Setup!$U50="","",IF(INDEX(SessionReviewTable[Patients Excluded - Missing Times],Setup!$U50)="","",INDEX(SessionReviewTable[Patients Excluded - Missing Times],Setup!$U50))) -> 0 | Q57: =IF(Setup!$U50="","",IF(INDEX(SessionReviewTable[Scheduling Notes],Setup!$U50)="","None",HYPERLINK("#'Review Data'!BH"&(Setup!$U50+5),"Open notes"))) -> None
B58: =IF(Setup!$U51="","",IF(INDEX(SessionReviewTable[Procedure Date],Setup!$U51)="","",INDEX(SessionReviewTable[Procedure Date],Setup!$U51))) -> 46259 | C58: =IF(Setup!$U51="","",IF(INDEX(SessionReviewTable[Operating Theatre],Setup!$U51)="","",INDEX(SessionReviewTable[Operating Theatre],Setup!$U51))) -> ST DHH MATERNITY THEATRE 1 | D58: =IF(Setup!$U51="","",IF(INDEX(SessionReviewTable[Session Specialty],Setup!$U51)="","",INDEX(SessionReviewTable[Session Specialty],Setup!$U51))) -> Obstetrics | E58: =IF(Setup!$U51="","",IF(INDEX(SessionReviewTable[Responsible Consultant],Setup!$U51)="","",INDEX(SessionReviewTable[Responsible Consultant],Setup!$U51))) -> Dr Dummy 09 | F58: =IF(Setup!$U51="","",IF(INDEX(SessionReviewTable[Slot Start Time],Setup!$U51)="","",INDEX(SessionReviewTable[Slot Start Time],Setup!$U51))) -> 46259.354 | G58: =IF(Setup!$U51="","",IF(INDEX(SessionReviewTable[Slot End Time],Setup!$U51)="","",INDEX(SessionReviewTable[Slot End Time],Setup!$U51))) -> 46259.479 | H58: =IF(Setup!$U51="","",IF(INDEX(SessionReviewTable[First Actual Start],Setup!$U51)="","",INDEX(SessionReviewTable[First Actual Start],Setup!$U51))) -> 46259.358 | I58: =IF(Setup!$U51="","",IF(INDEX(SessionReviewTable[Last Actual End],Setup!$U51)="","",INDEX(SessionReviewTable[Last Actual End],Setup!$U51))) -> 46259.474 | J58: =IF(Setup!$U51="","",IF(INDEX(SessionReviewTable[No of Patients],Setup!$U51)="","",INDEX(SessionReviewTable[No of Patients],Setup!$U51))) -> 4 | K58: =IF(Setup!$U51="","",IF(INDEX(SessionReviewTable[Run Minutes],Setup!$U51)="","",INDEX(SessionReviewTable[Run Minutes],Setup!$U51))) -> 166 | L58: =IF(Setup!$U51="","",IF(INDEX(SessionReviewTable[Op Minutes],Setup!$U51)="","",INDEX(SessionReviewTable[Op Minutes],Setup!$U51))) -> 80 | M58: =IF(Setup!$U51="","",IF(INDEX(SessionReviewTable[Start Type],Setup!$U51)="","",INDEX(SessionReviewTable[Start Type],Setup!$U51))) -> On Time | N58: =IF(Setup!$U51="","",IF(INDEX(SessionReviewTable[Finish Type],Setup!$U51)="","",INDEX(SessionReviewTable[Finish Type],Setup!$U51))) -> On Time | O58: =IF(Setup!$U51="","",IF(INDEX(SessionReviewTable[Timing Notes],Setup!$U51)="","None",HYPERLINK("#'Review Data'!AD"&(Setup!$U51+5),"Open notes"))) -> None | P58: =IF(Setup!$U51="","",IF(INDEX(SessionReviewTable[Patients Excluded - Missing Times],Setup!$U51)="","",INDEX(SessionReviewTable[Patients Excluded - Missing Times],Setup!$U51))) -> 0 | Q58: =IF(Setup!$U51="","",IF(INDEX(SessionReviewTable[Scheduling Notes],Setup!$U51)="","None",HYPERLINK("#'Review Data'!BH"&(Setup!$U51+5),"Open notes"))) -> None
B59: =IF(Setup!$U52="","",IF(INDEX(SessionReviewTable[Procedure Date],Setup!$U52)="","",INDEX(SessionReviewTable[Procedure Date],Setup!$U52))) -> 46259 | C59: =IF(Setup!$U52="","",IF(INDEX(SessionReviewTable[Operating Theatre],Setup!$U52)="","",INDEX(SessionReviewTable[Operating Theatre],Setup!$U52))) -> STY DPU 1 | D59: =IF(Setup!$U52="","",IF(INDEX(SessionReviewTable[Session Specialty],Setup!$U52)="","",INDEX(SessionReviewTable[Session Specialty],Setup!$U52))) -> ENT | E59: =IF(Setup!$U52="","",IF(INDEX(SessionReviewTable[Responsible Consultant],Setup!$U52)="","",INDEX(SessionReviewTable[Responsible Consultant],Setup!$U52))) -> Dr Dummy 21 | F59: =IF(Setup!$U52="","",IF(INDEX(SessionReviewTable[Slot Start Time],Setup!$U52)="","",INDEX(SessionReviewTable[Slot Start Time],Setup!$U52))) -> 46259.354 | G59: =IF(Setup!$U52="","",IF(INDEX(SessionReviewTable[Slot End Time],Setup!$U52)="","",INDEX(SessionReviewTable[Slot End Time],Setup!$U52))) -> 46259.479 | H59: =IF(Setup!$U52="","",IF(INDEX(SessionReviewTable[First Actual Start],Setup!$U52)="","",INDEX(SessionReviewTable[First Actual Start],Setup!$U52))) -> 46259.362 | I59: =IF(Setup!$U52="","",IF(INDEX(SessionReviewTable[Last Actual End],Setup!$U52)="","",INDEX(SessionReviewTable[Last Actual End],Setup!$U52))) -> 46259.471 | J59: =IF(Setup!$U52="","",IF(INDEX(SessionReviewTable[No of Patients],Setup!$U52)="","",INDEX(SessionReviewTable[No of Patients],Setup!$U52))) -> 4 | K59: =IF(Setup!$U52="","",IF(INDEX(SessionReviewTable[Run Minutes],Setup!$U52)="","",INDEX(SessionReviewTable[Run Minutes],Setup!$U52))) -> 157 | L59: =IF(Setup!$U52="","",IF(INDEX(SessionReviewTable[Op Minutes],Setup!$U52)="","",INDEX(SessionReviewTable[Op Minutes],Setup!$U52))) -> 85 | M59: =IF(Setup!$U52="","",IF(INDEX(SessionReviewTable[Start Type],Setup!$U52)="","",INDEX(SessionReviewTable[Start Type],Setup!$U52))) -> Late Start | N59: =IF(Setup!$U52="","",IF(INDEX(SessionReviewTable[Finish Type],Setup!$U52)="","",INDEX(SessionReviewTable[Finish Type],Setup!$U52))) -> Early Finish | O59: =IF(Setup!$U52="","",IF(INDEX(SessionReviewTable[Timing Notes],Setup!$U52)="","None",HYPERLINK("#'Review Data'!AD"&(Setup!$U52+5),"Open notes"))) -> None | P59: =IF(Setup!$U52="","",IF(INDEX(SessionReviewTable[Patients Excluded - Missing Times],Setup!$U52)="","",INDEX(SessionReviewTable[Patients Excluded - Missing Times],Setup!$U52))) -> 0 | Q59: =IF(Setup!$U52="","",IF(INDEX(SessionReviewTable[Scheduling Notes],Setup!$U52)="","None",HYPERLINK("#'Review Data'!BH"&(Setup!$U52+5),"Open notes"))) -> None
B60: =IF(Setup!$U53="","",IF(INDEX(SessionReviewTable[Procedure Date],Setup!$U53)="","",INDEX(SessionReviewTable[Procedure Date],Setup!$U53))) -> 46259 | C60: =IF(Setup!$U53="","",IF(INDEX(SessionReviewTable[Operating Theatre],Setup!$U53)="","",INDEX(SessionReviewTable[Operating Theatre],Setup!$U53))) -> ST STY THEATRE 1 | D60: =IF(Setup!$U53="","",IF(INDEX(SessionReviewTable[Session Specialty],Setup!$U53)="","",INDEX(SessionReviewTable[Session Specialty],Setup!$U53))) -> Gynaecology | E60: =IF(Setup!$U53="","",IF(INDEX(SessionReviewTable[Responsible Consultant],Setup!$U53)="","",INDEX(SessionReviewTable[Responsible Consultant],Setup!$U53))) -> Dr Dummy 04 | F60: =IF(Setup!$U53="","",IF(INDEX(SessionReviewTable[Slot Start Time],Setup!$U53)="","",INDEX(SessionReviewTable[Slot Start Time],Setup!$U53))) -> 46259.354 | G60: =IF(Setup!$U53="","",IF(INDEX(SessionReviewTable[Slot End Time],Setup!$U53)="","",INDEX(SessionReviewTable[Slot End Time],Setup!$U53))) -> 46259.688 | H60: =IF(Setup!$U53="","",IF(INDEX(SessionReviewTable[First Actual Start],Setup!$U53)="","",INDEX(SessionReviewTable[First Actual Start],Setup!$U53))) -> 46259.36 | I60: =IF(Setup!$U53="","",IF(INDEX(SessionReviewTable[Last Actual End],Setup!$U53)="","",INDEX(SessionReviewTable[Last Actual End],Setup!$U53))) -> 46259.669 | J60: =IF(Setup!$U53="","",IF(INDEX(SessionReviewTable[No of Patients],Setup!$U53)="","",INDEX(SessionReviewTable[No of Patients],Setup!$U53))) -> 4 | K60: =IF(Setup!$U53="","",IF(INDEX(SessionReviewTable[Run Minutes],Setup!$U53)="","",INDEX(SessionReviewTable[Run Minutes],Setup!$U53))) -> 446 | L60: =IF(Setup!$U53="","",IF(INDEX(SessionReviewTable[Op Minutes],Setup!$U53)="","",INDEX(SessionReviewTable[Op Minutes],Setup!$U53))) -> 316 | M60: =IF(Setup!$U53="","",IF(INDEX(SessionReviewTable[Start Type],Setup!$U53)="","",INDEX(SessionReviewTable[Start Type],Setup!$U53))) -> On Time | N60: =IF(Setup!$U53="","",IF(INDEX(SessionReviewTable[Finish Type],Setup!$U53)="","",INDEX(SessionReviewTable[Finish Type],Setup!$U53))) -> Early Finish | O60: =IF(Setup!$U53="","",IF(INDEX(SessionReviewTable[Timing Notes],Setup!$U53)="","None",HYPERLINK("#'Review Data'!AD"&(Setup!$U53+5),"Open notes"))) -> None | P60: =IF(Setup!$U53="","",IF(INDEX(SessionReviewTable[Patients Excluded - Missing Times],Setup!$U53)="","",INDEX(SessionReviewTable[Patients Excluded - Missing Times],Setup!$U53))) -> 0 | Q60: =IF(Setup!$U53="","",IF(INDEX(SessionReviewTable[Scheduling Notes],Setup!$U53)="","None",HYPERLINK("#'Review Data'!BH"&(Setup!$U53+5),"Open notes"))) -> None
B61: =IF(Setup!$U54="","",IF(INDEX(SessionReviewTable[Procedure Date],Setup!$U54)="","",INDEX(SessionReviewTable[Procedure Date],Setup!$U54))) -> 46259 | C61: =IF(Setup!$U54="","",IF(INDEX(SessionReviewTable[Operating Theatre],Setup!$U54)="","",INDEX(SessionReviewTable[Operating Theatre],Setup!$U54))) -> ST STY THEATRE 2 | D61: =IF(Setup!$U54="","",IF(INDEX(SessionReviewTable[Session Specialty],Setup!$U54)="","",INDEX(SessionReviewTable[Session Specialty],Setup!$U54))) -> Oral and Maxillofacial Surgery | E61: =IF(Setup!$U54="","",IF(INDEX(SessionReviewTable[Responsible Consultant],Setup!$U54)="","",INDEX(SessionReviewTable[Responsible Consultant],Setup!$U54))) -> Dr Dummy 08 | F61: =IF(Setup!$U54="","",IF(INDEX(SessionReviewTable[Slot Start Time],Setup!$U54)="","",INDEX(SessionReviewTable[Slot Start Time],Setup!$U54))) -> 46259.333 | G61: =IF(Setup!$U54="","",IF(INDEX(SessionReviewTable[Slot End Time],Setup!$U54)="","",INDEX(SessionReviewTable[Slot End Time],Setup!$U54))) -> 46259.625 | H61: =IF(Setup!$U54="","",IF(INDEX(SessionReviewTable[First Actual Start],Setup!$U54)="","",INDEX(SessionReviewTable[First Actual Start],Setup!$U54))) -> 46259.339 | I61: =IF(Setup!$U54="","",IF(INDEX(SessionReviewTable[Last Actual End],Setup!$U54)="","",INDEX(SessionReviewTable[Last Actual End],Setup!$U54))) -> 46259.61 | J61: =IF(Setup!$U54="","",IF(INDEX(SessionReviewTable[No of Patients],Setup!$U54)="","",INDEX(SessionReviewTable[No of Patients],Setup!$U54))) -> 4 | K61: =IF(Setup!$U54="","",IF(INDEX(SessionReviewTable[Run Minutes],Setup!$U54)="","",INDEX(SessionReviewTable[Run Minutes],Setup!$U54))) -> 390 | L61: =IF(Setup!$U54="","",IF(INDEX(SessionReviewTable[Op Minutes],Setup!$U54)="","",INDEX(SessionReviewTable[Op Minutes],Setup!$U54))) -> 261 | M61: =IF(Setup!$U54="","",IF(INDEX(SessionReviewTable[Start Type],Setup!$U54)="","",INDEX(SessionReviewTable[Start Type],Setup!$U54))) -> On Time | N61: =IF(Setup!$U54="","",IF(INDEX(SessionReviewTable[Finish Type],Setup!$U54)="","",INDEX(SessionReviewTable[Finish Type],Setup!$U54))) -> Early Finish | O61: =IF(Setup!$U54="","",IF(INDEX(SessionReviewTable[Timing Notes],Setup!$U54)="","None",HYPERLINK("#'Review Data'!AD"&(Setup!$U54+5),"Open notes"))) -> None | P61: =IF(Setup!$U54="","",IF(INDEX(SessionReviewTable[Patients Excluded - Missing Times],Setup!$U54)="","",INDEX(SessionReviewTable[Patients Excluded - Missing Times],Setup!$U54))) -> 0 | Q61: =IF(Setup!$U54="","",IF(INDEX(SessionReviewTable[Scheduling Notes],Setup!$U54)="","None",HYPERLINK("#'Review Data'!BH"&(Setup!$U54+5),"Open notes"))) -> None
B62: =IF(Setup!$U55="","",IF(INDEX(SessionReviewTable[Procedure Date],Setup!$U55)="","",INDEX(SessionReviewTable[Procedure Date],Setup!$U55))) -> 46260 | C62: =IF(Setup!$U55="","",IF(INDEX(SessionReviewTable[Operating Theatre],Setup!$U55)="","",INDEX(SessionReviewTable[Operating Theatre],Setup!$U55))) -> ST CAH MAIN THEATRE 7 | D62: =IF(Setup!$U55="","",IF(INDEX(SessionReviewTable[Session Specialty],Setup!$U55)="","",INDEX(SessionReviewTable[Session Specialty],Setup!$U55))) -> ENT | E62: =IF(Setup!$U55="","",IF(INDEX(SessionReviewTable[Responsible Consultant],Setup!$U55)="","",INDEX(SessionReviewTable[Responsible Consultant],Setup!$U55))) -> Dr Dummy 20 | F62: =IF(Setup!$U55="","",IF(INDEX(SessionReviewTable[Slot Start Time],Setup!$U55)="","",INDEX(SessionReviewTable[Slot Start Time],Setup!$U55))) -> 46260.333 | G62: =IF(Setup!$U55="","",IF(INDEX(SessionReviewTable[Slot End Time],Setup!$U55)="","",INDEX(SessionReviewTable[Slot End Time],Setup!$U55))) -> 46260.479 | H62: =IF(Setup!$U55="","",IF(INDEX(SessionReviewTable[First Actual Start],Setup!$U55)="","",INDEX(SessionReviewTable[First Actual Start],Setup!$U55))) -> 46260.337 | I62: =IF(Setup!$U55="","",IF(INDEX(SessionReviewTable[Last Actual End],Setup!$U55)="","",INDEX(SessionReviewTable[Last Actual End],Setup!$U55))) -> 46260.46 | J62: =IF(Setup!$U55="","",IF(INDEX(SessionReviewTable[No of Patients],Setup!$U55)="","",INDEX(SessionReviewTable[No of Patients],Setup!$U55))) -> 4 | K62: =IF(Setup!$U55="","",IF(INDEX(SessionReviewTable[Run Minutes],Setup!$U55)="","",INDEX(SessionReviewTable[Run Minutes],Setup!$U55))) -> 178 | L62: =IF(Setup!$U55="","",IF(INDEX(SessionReviewTable[Op Minutes],Setup!$U55)="","",INDEX(SessionReviewTable[Op Minutes],Setup!$U55))) -> 105 | M62: =IF(Setup!$U55="","",IF(INDEX(SessionReviewTable[Start Type],Setup!$U55)="","",INDEX(SessionReviewTable[Start Type],Setup!$U55))) -> On Time | N62: =IF(Setup!$U55="","",IF(INDEX(SessionReviewTable[Finish Type],Setup!$U55)="","",INDEX(SessionReviewTable[Finish Type],Setup!$U55))) -> Early Finish | O62: =IF(Setup!$U55="","",IF(INDEX(SessionReviewTable[Timing Notes],Setup!$U55)="","None",HYPERLINK("#'Review Data'!AD"&(Setup!$U55+5),"Open notes"))) -> None | P62: =IF(Setup!$U55="","",IF(INDEX(SessionReviewTable[Patients Excluded - Missing Times],Setup!$U55)="","",INDEX(SessionReviewTable[Patients Excluded - Missing Times],Setup!$U55))) -> 0 | Q62: =IF(Setup!$U55="","",IF(INDEX(SessionReviewTable[Scheduling Notes],Setup!$U55)="","None",HYPERLINK("#'Review Data'!BH"&(Setup!$U55+5),"Open notes"))) -> None
